Workbook
Name Slicer_Clean_Status: #N/A
Name Slicer_Customer_City: #N/A
Name Slicer_Order_Month: #N/A
Name Slicer_Payment_Method: #N/A
Name Slicer_Restaurant_Name: #N/A

Sheet Row data wise pivote Analysis
B1: Order Status Analysis | F1: Operations Alert | J1: City-wise Orders | N1: Restaurant-wise Orders | R1: Restaurant Revenue | U1: Restaurant name wise net revenue | Y1: Operations Alert Pivot | AD1: Monthly Revenue
A3: Row Labels | B3: Count of Order_ID
A4: Cancelled | B4: 51 | E4: Row Labels | F4: Count of Operations_Alert | Q4: Row Labels | R4: Sum of Net_Revenue | U4: Row Labels | V4: Sum of Net_Revenue
A5: Delivered | B5: 215 | E5: Attention - Low Rating | F5: 39 | I5: Row Labels | J5: Count of Order_ID | Q5: Biryani House | R5: 16397.75 | U5: Pune Bites | V5: 24783.23 | Y5: Row Labels | Z5: Count of Order_ID
A6: Escalated | B6: 34 | E6: Critical - Cancelled | F6: 50 | I6: Bengaluru | J6: 50 | M6: Row Labels | N6: Count of Order_ID | Q6: Burger Garage | R6: 7748.96 | U6: Royal Thali | V6: 19227.23 | Y6: Attention - Low Rating | Z6: 39 | AC6: Row Labels | AD6: Sum of Net_Revenue
A7: Grand Total | B7: 300 | E7: Critical - Late Delivery | F7: 41 | I7: Hyderabad | J7: 38 | M7: Biryani House | N7: 14 | Q7: Cafe Aroma | R7: 13501.65 | U7: Tandoor Tales | V7: 18203.97 | Y7: Critical - Cancelled | Z7: 50 | AC7: May | AD7: 118074.57
E8: Normal | F8: 170 | I8: Mumbai | J8: 55 | M8: Burger Garage | N8: 8 | Q8: Chinese Wok | R8: 13620.22 | U8: Wok Express | V8: 18129.15 | Y8: Critical - Late Delivery | Z8: 41 | AC8: Jun | AD8: 112680.7
E9: Grand Total | F9: 300 | I9: Nagpur | J9: 55 | M9: Cafe Aroma | N9: 11 | Q9: Curry Leaf | R9: 14171.79 | U9: Dosa Junction | V9: 18059.57 | Y9: Normal | Z9: 170 | AC9: Jul | AD9: 115365.11
I10: Nashik | J10: 21 | M10: Chinese Wok | N10: 13 | Q10: Dosa Junction | R10: 18059.57 | U10: Spice Hub | V10: 17080.28 | Y10: Grand Total | Z10: 300 | AC10: Grand Total | AD10: 346120.38
I11: Pune | J11: 81 | M11: Curry Leaf | N11: 13 | Q11: Green Bowl | R11: 14766.23 | U11: Biryani House | V11: 16397.75
I12: Grand Total | J12: 300 | M12: Dosa Junction | N12: 14 | Q12: Grill House | R12: 15448.65 | U12: Grill House | V12: 15448.65
M13: Green Bowl | N13: 12 | Q13: Healthy Harvest | R13: 9914.63 | U13: Kebab Nation | V13: 15122.29
M14: Grill House | N14: 13 | Q14: Kebab Nation | R14: 15122.29 | U14: South Spice | V14: 14973.87
M15: Healthy Harvest | N15: 10 | Q15: Maharashtra Kitchen | R15: 10028.14 | U15: Green Bowl | V15: 14766.23
M16: Kebab Nation | N16: 15 | Q16: Mumbai Masala | R16: 9050.69 | U16: Pasta Point | V16: 14184.46
M17: Maharashtra Kitchen | N17: 10 | Q17: Pasta Point | R17: 14184.46 | U17: Curry Leaf | V17: 14171.79
M18: Mumbai Masala | N18: 8 | Q18: Pizza Craft | R18: 10240.29 | U18: Chinese Wok | V18: 13620.22
M19: Pasta Point | N19: 12 | Q19: Pune Bites | R19: 24783.23 | U19: Cafe Aroma | V19: 13501.65
M20: Pizza Craft | N20: 9 | Q20: Royal Thali | R20: 19227.23 | U20: Wrap Street | V20: 12037.7
M21: Pune Bites | N21: 20 | Q21: South Spice | R21: 14973.87 | U21: The Breakfast Club | V21: 11200.01
M22: Royal Thali | N22: 17 | Q22: Spice Hub | R22: 17080.28 | U22: Urban Tadka | V22: 10479.17
M23: South Spice | N23: 11 | Q23: Sweet Truth | R23: 10237.77 | U23: Pizza Craft | V23: 10240.29
M24: Spice Hub | N24: 17 | Q24: Tandoor Tales | R24: 18203.97 | U24: Sweet Truth | V24: 10237.77
... M30: Wok Express | N30: 16 | Q30: Grand Total | R30: 346120.38 | U30: Grand Total | V30: 346120.38
M31: Wrap Street | N31: 11
M32: Grand Total | N32: 300

Sheet Dashboard
I4: Total Revenue | K4: Total Orders | M4: Cancellation Rate | O4: Average Delivery Time | Q4: Average Customer Rating
I5: =SUM(Table1[Net_Revenue]) -> 346120.38 | K5: =COUNTA(Table1[Order_ID]) -> 300 | M5: =COUNTIF(Table1[Order_Status],"Cancelled")/COUNTA(Table1[Order_ID]) -> 0.16666667 | O5: =AVERAGE(Table1[Delivery_Time_Min]) -> 36.563333 | Q5: =AVERAGE(Table1[Customer_Rating]) -> 4.1471963

Sheet Raw_Orders
A1: Order_ID | B1: Order_Date | C1: Customer_ID | D1: Restaurant_ID | E1: Delivery_Partner_ID | F1: Order_Value | G1: Delivery_Fee | H1: Discount | I1: Distance_KM | J1: Delivery_Time_Min | K1: Customer_Rating | L1: Order_Status | M1: Clean_Status | N1: Payment_Method | O1: Clean_Payment_Method | P1: Coupon_Code | Q1: Clean_Coupon_Code | R1: Campaign_ID | S1: Cancellation_Reason | T1: Customer_Name | U1: Restaurant_Name | V1: Delivery_Partner_Name | W1: Campaign_Name | X1: Net_Revenue | Y1: Delivery SLA Status | Z1: Operations_Alert | AA1: Customer_City | AB1: Order_Month
A2: ORD00089 | B2: 46229 | C2: CUST060 | D2: REST005 | E2: DP012 | F2: 624.66 | G2: 35 | H2: 70.16 | I2: 6 | J2: 41 | K2: 4.5 | L2: CANCELLED | M2: =PROPER(TRIM(L2)) -> Cancelled | N2: Credit Card | O2: =TRIM(N2) -> Credit Card | P2: BUDGET50 | Q2: =TRIM(P2) -> BUDGET50 | R2: CMP003 | T2: =_xlfn.XLOOKUP(Table1[[#This Row],[Customer_ID]],Customers!A:A,Customers!B:B) -> Aditya Patil | U2: =_xlfn.XLOOKUP(Table1[[#This Row],[Restaurant_ID]],Restaurants!A:A,Restaurants!B:B) -> Green Bowl | V2: =_xlfn.XLOOKUP(Table1[[#This Row],[Delivery_Partner_ID]],Delivery_Partners!A:A,Delivery_Partners!B:B) -> Manoj | W2: =_xlfn.XLOOKUP(Table1[[#This Row],[Campaign_ID]],Campaigns!A:A,Campaigns!B:B) -> Premium Treat | X2: =Table1[[#This Row],[Order_Value]]+Table1[[#This Row],[Delivery_Fee]]-Table1[[#This Row],[Discount]] -> 589.5 | Y2: {=_xlfn.IFS(Table1[[#This Row],[Delivery_Time_Min]]<=30,"On Time",Table1[[#This Row],[Delivery_Time_Min]]<=45,"At Risk",TRUE,"SLA Breach")} -> At Risk | Z2: {=_xlfn.IFS( Table1[[#This Row],[Order_Status]]="Cancelled","Critical - Cancelled", Table1[[#This Row],[Delivery SLA Status]]="SLA Breach","Critical - Late Delivery", Table1[[#This Row],[Customer_Rating]]<3,"Attention - Low Rating", TRUE,"Normal" )} -> Normal | AA2: =_xlfn.XLOOKUP(Table1[[#This Row],[Customer_ID]],Customers!A:A,Customers!C:C) -> Nashik | AB2: =TEXT(Table1[[#This Row],[Order_Date]],"mmm") -> Jul
A3: ORD00008 | B3: 46158 | C3: CUST004 | D3: REST010 | E3: DP017 | F3: 1210.99 | G3: 35 | H3: 195.15 | I3: 4.8 | J3: 30 | L3: Cancelled | M3: =PROPER(TRIM(L3)) -> Cancelled | N3: Cash on Delivery | O3: =TRIM(N3) -> Cash on Delivery | P3: SAVE100 | Q3: =TRIM(P3) -> SAVE100 | R3: CMP002 | S3: Delivery partner unavailable | T3: =_xlfn.XLOOKUP(Table1[[#This Row],[Customer_ID]],Customers!A:A,Customers!B:B) -> Isha Pawar | U3: =_xlfn.XLOOKUP(Table1[[#This Row],[Restaurant_ID]],Restaurants!A:A,Restaurants!B:B) -> Dosa Junction | V3: =_xlfn.XLOOKUP(Table1[[#This Row],[Delivery_Partner_ID]],Delivery_Partners!A:A,Delivery_Partners!B:B) -> Sanjay | W3: =_xlfn.XLOOKUP(Table1[[#This Row],[Campaign_ID]],Campaigns!A:A,Campaigns!B:B) -> New User Boost | X3: =Table1[[#This Row],[Order_Value]]+Table1[[#This Row],[Delivery_Fee]]-Table1[[#This Row],[Discount]] -> 1050.84 | Y3: {=_xlfn.IFS(Table1[[#This Row],[Delivery_Time_Min]]<=30,"On Time",Table1[[#This Row],[Delivery_Time_Min]]<=45,"At Risk",TRUE,"SLA Breach")} -> On Time | Z3: {=_xlfn.IFS( Table1[[#This Row],[Order_Status]]="Cancelled","Critical - Cancelled", Table1[[#This Row],[Delivery SLA Status]]="SLA Breach","Critical - Late Delivery", Table1[[#This Row],[Customer_Rating]]<3,"Attention - Low Rating", TRUE,"Normal" )} -> Critical - Cancelled | AA3: =_xlfn.XLOOKUP(Table1[[#This Row],[Customer_ID]],Customers!A:A,Customers!C:C) -> Pune | AB3: =TEXT(Table1[[#This Row],[Order_Date]],"mmm") -> May
A4: ORD00011 | B4: 46149 | C4: CUST052 | D4: REST015 | E4: DP015 | F4: 1129.47 | G4: 30 | H4: 204.29 | I4: 1.7 | J4: 27 | L4: Cancelled | M4: =PROPER(TRIM(L4)) -> Cancelled | N4: Debit Card | O4: =TRIM(N4) -> Debit Card | P4: PREMIUM10 | Q4: =TRIM(P4) -> PREMIUM10 | R4: CMP007 | S4: Delivery partner unavailable | T4: =_xlfn.XLOOKUP(Table1[[#This Row],[Customer_ID]],Customers!A:A,Customers!B:B) -> Aarav Sharma | U4: =_xlfn.XLOOKUP(Table1[[#This Row],[Restaurant_ID]],Restaurants!A:A,Restaurants!B:B) -> Royal Thali | V4: =_xlfn.XLOOKUP(Table1[[#This Row],[Delivery_Partner_ID]],Delivery_Partners!A:A,Delivery_Partners!B:B) -> Vivek | W4: =_xlfn.XLOOKUP(Table1[[#This Row],[Campaign_ID]],Campaigns!A:A,Campaigns!B:B) -> First Order | X4: =Table1[[#This Row],[Order_Value]]+Table1[[#This Row],[Delivery_Fee]]-Table1[[#This Row],[Discount]] -> 955.18 | Y4: {=_xlfn.IFS(Table1[[#This Row],[Delivery_Time_Min]]<=30,"On Time",Table1[[#This Row],[Delivery_Time_Min]]<=45,"At Risk",TRUE,"SLA Breach")} -> On Time | Z4: {=_xlfn.IFS( Table1[[#This Row],[Order_Status]]="Cancelled","Critical - Cancelled", Table1[[#This Row],[Delivery SLA Status]]="SLA Breach","Critical - Late Delivery", Table1[[#This Row],[Customer_Rating]]<3,"Attention - Low Rating", TRUE,"Normal" )} -> Critical - Cancelled | AA4: =_xlfn.XLOOKUP(Table1[[#This Row],[Customer_ID]],Customers!A:A,Customers!C:C) -> Pune | AB4: =TEXT(Table1[[#This Row],[Order_Date]],"mmm") -> May
A5: ORD00014 | B5: 46145 | C5: CUST006 | D5: REST020 | E5: DP002 | F5: 609.25 | G5: 30 | H5: 69.72 | I5: 2.8 | J5: 33 | L5: Cancelled | M5: =PROPER(TRIM(L5)) -> Cancelled | N5: Wallet | O5: =TRIM(N5) -> Wallet | P5: SAVE100 | Q5: =TRIM(P5) -> SAVE100 | R5: CMP003 | S5: Restaurant delay | T5: =_xlfn.XLOOKUP(Table1[[#This Row],[Customer_ID]],Customers!A:A,Customers!B:B) -> Pooja Desai | U5: =_xlfn.XLOOKUP(Table1[[#This Row],[Restaurant_ID]],Restaurants!A:A,Restaurants!B:B) -> Wrap Street | V5: =_xlfn.XLOOKUP(Table1[[#This Row],[Delivery_Partner_ID]],Delivery_Partners!A:A,Delivery_Partners!B:B) -> Amit | W5: =_xlfn.XLOOKUP(Table1[[#This Row],[Campaign_ID]],Campaigns!A:A,Campaigns!B:B) -> Premium Treat | X5: =Table1[[#This Row],[Order_Value]]+Table1[[#This Row],[Delivery_Fee]]-Table1[[#This Row],[Discount]] -> 569.53 | Y5: {=_xlfn.IFS(Table1[[#This Row],[Delivery_Time_Min]]<=30,"On Time",Table1[[#This Row],[Delivery_Time_Min]]<=45,"At Risk",TRUE,"SLA Breach")} -> At Risk | Z5: {=_xlfn.IFS( Table1[[#This Row],[Order_Status]]="Cancelled","Critical - Cancelled", Table1[[#This Row],[Delivery SLA Status]]="SLA Breach","Critical - Late Delivery", Table1[[#This Row],[Customer_Rating]]<3,"Attention - Low Rating", TRUE,"Normal" )} -> Critical - Cancelled | AA5: =_xlfn.XLOOKUP(Table1[[#This Row],[Customer_ID]],Customers!A:A,Customers!C:C) -> Mumbai | AB5: =TEXT(Table1[[#This Row],[Order_Date]],"mmm") -> May
A6: ORD00024 | B6: 46231 | C6: CUST020 | D6: REST011 | E6: DP010 | F6: 509.41 | G6: 20 | H6: 0 | I6: 2.7 | J6: 39 | L6: Cancelled | M6: =PROPER(TRIM(L6)) -> Cancelled | N6: Cash on Delivery | O6: =TRIM(N6) -> Cash on Delivery | P6: NONE | Q6: =TRIM(P6) -> NONE | R6: CMP008 | S6: Customer changed mind | T6: =_xlfn.XLOOKUP(Table1[[#This Row],[Customer_ID]],Customers!A:A,Customers!B:B) -> Isha More | U6: =_xlfn.XLOOKUP(Table1[[#This Row],[Restaurant_ID]],Restaurants!A:A,Restaurants!B:B) -> Wok Express | V6: =_xlfn.XLOOKUP(Table1[[#This Row],[Delivery_Partner_ID]],Delivery_Partners!A:A,Delivery_Partners!B:B) -> Nitin | W6: =_xlfn.XLOOKUP(Table1[[#This Row],[Campaign_ID]],Campaigns!A:A,Campaigns!B:B) -> Monsoon Meals | X6: =Table1[[#This Row],[Order_Value]]+Table1[[#This Row],[Delivery_Fee]]-Table1[[#This Row],[Discount]] -> 529.41 | Y6: {=_xlfn.IFS(Table1[[#This Row],[Delivery_Time_Min]]<=30,"On Time",Table1[[#This Row],[Delivery_Time_Min]]<=45,"At Risk",TRUE,"SLA Breach")} -> At Risk | Z6: {=_xlfn.IFS( Table1[[#This Row],[Order_Status]]="Cancelled","Critical - Cancelled", Table1[[#This Row],[Delivery SLA Status]]="SLA Breach","Critical - Late Delivery", Table1[[#This Row],[Customer_Rating]]<3,"Attention - Low Rating", TRUE,"Normal" )} -> Critical - Cancelled | AA6: =_xlfn.XLOOKUP(Table1[[#This Row],[Customer_ID]],Customers!A:A,Customers!C:C) -> Pune | AB6: =TEXT(Table1[[#This Row],[Order_Date]],"mmm") -> Jul
A7: ORD00026 | B7: 46168 | C7: CUST054 | D7: REST023 | E7: DP001 | F7: 715.38 | G7: 20 | H7: 131.77 | I7: 3.3 | J7: 25 | L7: Cancelled | M7: =PROPER(TRIM(L7)) -> Cancelled | N7: Debit Card | O7: =TRIM(N7) -> Debit Card | P7: LUNCH15 | Q7: =TRIM(P7) -> LUNCH15 | R7: CMP007 | S7: Restaurant unavailable | T7: =_xlfn.XLOOKUP(Table1[[#This Row],[Customer_ID]],Customers!A:A,Customers!B:B) -> Nikhil Joshi | U7: =_xlfn.XLOOKUP(Table1[[#This Row],[Restaurant_ID]],Restaurants!A:A,Restaurants!B:B) -> Maharashtra Kitchen | V7: =_xlfn.XLOOKUP(Table1[[#This Row],[Delivery_Partner_ID]],Delivery_Partners!A:A,Delivery_Partners!B:B) -> Rahul | W7: =_xlfn.XLOOKUP(Table1[[#This Row],[Campaign_ID]],Campaigns!A:A,Campaigns!B:B) -> First Order | X7: =Table1[[#This Row],[Order_Value]]+Table1[[#This Row],[Delivery_Fee]]-Table1[[#This Row],[Discount]] -> 603.61 | Y7: {=_xlfn.IFS(Table1[[#This Row],[Delivery_Time_Min]]<=30,"On Time",Table1[[#This Row],[Delivery_Time_Min]]<=45,"At Risk",TRUE,"SLA Breach")} -> On Time | Z7: {=_xlfn.IFS( Table1[[#This Row],[Order_Status]]="Cancelled","Critical - Cancelled", Table1[[#This Row],[Delivery SLA Status]]="SLA Breach","Critical - Late Delivery", Table1[[#This Row],[Customer_Rating]]<3,"Attention - Low Rating", TRUE,"Normal" )} -> Critical - Cancelled | AA7: =_xlfn.XLOOKUP(Table1[[#This Row],[Customer_ID]],Customers!A:A,Customers!C:C) -> Nagpur | AB7: =TEXT(Table1[[#This Row],[Order_Date]],"mmm") -> May
A8: ORD00028 | B8: 46162 | C8: CUST070 | D8: REST021 | E8: DP001 | F8: 834.8 | G8: 50 | H8: 126.99 | I8: 11.7 | J8: 53 | L8: Cancelled | M8: =PROPER(TRIM(L8)) -> Cancelled | N8: Cash on Delivery | O8: =TRIM(N8) -> Cash on Delivery | P8: SAVE100 | Q8: =TRIM(P8) -> SAVE100 | R8: CMP001 | S8: Restaurant delay | T8: =_xlfn.XLOOKUP(Table1[[#This Row],[Customer_ID]],Customers!A:A,Customers!B:B) -> Sakshi Shinde | U8: =_xlfn.XLOOKUP(Table1[[#This Row],[Restaurant_ID]],Restaurants!A:A,Restaurants!B:B) -> Grill House | V8: =_xlfn.XLOOKUP(Table1[[#This Row],[Delivery_Partner_ID]],Delivery_Partners!A:A,Delivery_Partners!B:B) -> Rahul | W8: =_xlfn.XLOOKUP(Table1[[#This Row],[Campaign_ID]],Campaigns!A:A,Campaigns!B:B) -> Weekend Feast | X8: =Table1[[#This Row],[Order_Value]]+Table1[[#This Row],[Delivery_Fee]]-Table1[[#This Row],[Discount]] -> 757.81 | Y8: {=_xlfn.IFS(Table1[[#This Row],[Delivery_Time_Min]]<=30,"On Time",Table1[[#This Row],[Delivery_Time_Min]]<=45,"At Risk",TRUE,"SLA Breach")} -> SLA Breach | Z8: {=_xlfn.IFS( Table1[[#This Row],[Order_Status]]="Cancelled","Critical - Cancelled", Table1[[#This Row],[Delivery SLA Status]]="SLA Breach","Critical - Late Delivery", Table1[[#This Row],[Customer_Rating]]<3,"Attention - Low Rating", TRUE,"Normal" )} -> Critical - Cancelled | AA8: =_xlfn.XLOOKUP(Table1[[#This Row],[Customer_ID]],Customers!A:A,Customers!C:C) -> Hyderabad | AB8: =TEXT(Table1[[#This Row],[Order_Date]],"mmm") -> May
A9: ORD00030 | B9: 46197 | C9: CUST001 | D9: REST014 | E9: DP019 | F9: 2900.74 | G9: 60 | H9: 300 | I9: 2.1 | J9: 41 | L9: Cancelled | M9: =PROPER(TRIM(L9)) -> Cancelled | N9: Debit Card | O9: =TRIM(N9) -> Debit Card | P9: PREMIUM10 | Q9: =TRIM(P9) -> PREMIUM10 | R9: CMP007 | S9: Restaurant unavailable | T9: =_xlfn.XLOOKUP(Table1[[#This Row],[Customer_ID]],Customers!A:A,Customers!B:B) -> Neha Kulkarni | U9: =_xlfn.XLOOKUP(Table1[[#This Row],[Restaurant_ID]],Restaurants!A:A,Restaurants!B:B) -> Sweet Truth | V9: =_xlfn.XLOOKUP(Table1[[#This Row],[Delivery_Partner_ID]],Delivery_Partners!A:A,Delivery_Partners!B:B) -> Ajay | W9: =_xlfn.XLOOKUP(Table1[[#This Row],[Campaign_ID]],Campaigns!A:A,Campaigns!B:B) -> First Order | X9: =Table1[[#This Row],[Order_Value]]+Table1[[#This Row],[Delivery_Fee]]-Table1[[#This Row],[Discount]] -> 2660.74 | Y9: {=_xlfn.IFS(Table1[[#This Row],[Delivery_Time_Min]]<=30,"On Time",Table1[[#This Row],[Delivery_Time_Min]]<=45,"At Risk",TRUE,"SLA Breach")} -> At Risk | Z9: {=_xlfn.IFS( Table1[[#This Row],[Order_Status]]="Cancelled","Critical - Cancelled", Table1[[#This Row],[Delivery SLA Status]]="SLA Breach","Critical - Late Delivery", Table1[[#This Row],[Customer_Rating]]<3,"Attention - Low Rating", TRUE,"Normal" )} -> Critical - Cancelled | AA9: =_xlfn.XLOOKUP(Table1[[#This Row],[Customer_ID]],Customers!A:A,Customers!C:C) -> Nagpur | AB9: =TEXT(Table1[[#This Row],[Order_Date]],"mmm") -> Jun
A10: ORD00032 | B10: 46158 | C10: CUST072 | D10: REST022 | E10: DP015 | F10: 1414.16 | G10: 35 | H10: 161.28 | I10: 8.9 | J10: 34 | L10: Cancelled | M10: =PROPER(TRIM(L10)) -> Cancelled | N10: Cash on Delivery | O10: =TRIM(N10) -> Cash on Delivery | P10: WELCOME50 | Q10: =TRIM(P10) -> WELCOME50 | R10: CMP005 | S10: Delivery partner unavailable | T10: =_xlfn.XLOOKUP(Table1[[#This Row],[Customer_ID]],Customers!A:A,Customers!B:B) -> Sakshi Desai | U10: =_xlfn.XLOOKUP(Table1[[#This Row],[Restaurant_ID]],Restaurants!A:A,Restaurants!B:B) -> Chinese Wok | V10: =_xlfn.XLOOKUP(Table1[[#This Row],[Delivery_Partner_ID]],Delivery_Partners!A:A,Delivery_Partners!B:B) -> Vivek | W10: =_xlfn.XLOOKUP(Table1[[#This Row],[Campaign_ID]],Campaigns!A:A,Campaigns!B:B) -> Budget Bites | X10: =Table1[[#This Row],[Order_Value]]+Table1[[#This Row],[Delivery_Fee]]-Table1[[#This Row],[Discount]] -> 1287.88 | Y10: {=_xlfn.IFS(Table1[[#This Row],[Delivery_Time_Min]]<=30,"On Time",Table1[[#This Row],[Delivery_Time_Min]]<=45,"At Risk",TRUE,"SLA Breach")} -> At Risk | Z10: {=_xlfn.IFS( Table1[[#This Row],[Order_Status]]="Cancelled","Critical - Cancelled", Table1[[#This Row],[Delivery SLA Status]]="SLA Breach","Critical - Late Delivery", Table1[[#This Row],[Customer_Rating]]<3,"Attention - Low Rating", TRUE,"Normal" )} -> Critical - Cancelled | AA10: =_xlfn.XLOOKUP(Table1[[#This Row],[Customer_ID]],Customers!A:A,Customers!C:C) -> Hyderabad | AB10: =TEXT(Table1[[#This Row],[Order_Date]],"mmm") -> May
A11: ORD00034 | B11: 46195 | C11: CUST001 | D11: REST015 | E11: DP005 | F11: 1729.74 | G11: 35 | H11: 300 | I11: 4.8 | J11: 30 | L11: Cancelled | M11: =PROPER(TRIM(L11)) -> Cancelled | N11: Debit Card | O11: =TRIM(N11) -> Debit Card | P11: WELCOME50 | Q11: =TRIM(P11) -> WELCOME50 | R11: CMP004 | S11: Customer changed mind | T11: =_xlfn.XLOOKUP(Table1[[#This Row],[Customer_ID]],Customers!A:A,Customers!B:B) -> Neha Kulkarni | U11: =_xlfn.XLOOKUP(Table1[[#This Row],[Restaurant_ID]],Restaurants!A:A,Restaurants!B:B) -> Royal Thali | V11: =_xlfn.XLOOKUP(Table1[[#This Row],[Delivery_Partner_ID]],Delivery_Partners!A:A,Delivery_Partners!B:B) -> Ravi | W11: =_xlfn.XLOOKUP(Table1[[#This Row],[Campaign_ID]],Campaigns!A:A,Campaigns!B:B) -> Lunch Saver | X11: =Table1[[#This Row],[Order_Value]]+Table1[[#This Row],[Delivery_Fee]]-Table1[[#This Row],[Discount]] -> 1464.74 | Y11: {=_xlfn.IFS(Table1[[#This Row],[Delivery_Time_Min]]<=30,"On Time",Table1[[#This Row],[Delivery_Time_Min]]<=45,"At Risk",TRUE,"SLA Breach")} -> On Time | Z11: {=_xlfn.IFS( Table1[[#This Row],[Order_Status]]="Cancelled","Critical - Cancelled", Table1[[#This Row],[Delivery SLA Status]]="SLA Breach","Critical - Late Delivery", Table1[[#This Row],[Customer_Rating]]<3,"Attention - Low Rating", TRUE,"Normal" )} -> Critical - Cancelled | AA11: =_xlfn.XLOOKUP(Table1[[#This Row],[Customer_ID]],Customers!A:A,Customers!C:C) -> Nagpur | AB11: =TEXT(Table1[[#This Row],[Order_Date]],"mmm") -> Jun
A12: ORD00035 | B12: 46167 | C12: CUST024 | D12: REST017 | E12: DP010 | F12: 1707.44 | G12: 60 | H12: 141.97 | I12: 4 | J12: 31 | L12: Cancelled | M12: =PROPER(TRIM(L12)) -> Cancelled | N12: UPI | O12: =TRIM(N12) -> UPI | P12: LUNCH15 | Q12: =TRIM(P12) -> LUNCH15 | R12: CMP006 | S12: Customer changed mind | T12: =_xlfn.XLOOKUP(Table1[[#This Row],[Customer_ID]],Customers!A:A,Customers!B:B) -> Neha Kulkarni | U12: =_xlfn.XLOOKUP(Table1[[#This Row],[Restaurant_ID]],Restaurants!A:A,Restaurants!B:B) -> Kebab Nation | V12: =_xlfn.XLOOKUP(Table1[[#This Row],[Delivery_Partner_ID]],Delivery_Partners!A:A,Delivery_Partners!B:B) -> Nitin | W12: =_xlfn.XLOOKUP(Table1[[#This Row],[Campaign_ID]],Campaigns!A:A,Campaigns!B:B) -> Festival Special | X12: =Table1[[#This Row],[Order_Value]]+Table1[[#This Row],[Delivery_Fee]]-Table1[[#This Row],[Discount]] -> 1625.47 | Y12: {=_xlfn.IFS(Table1[[#This Row],[Delivery_Time_Min]]<=30,"On Time",Table1[[#This Row],[Delivery_Time_Min]]<=45,"At Risk",TRUE,"SLA Breach")} -> At Risk | Z12: {=_xlfn.IFS( Table1[[#This Row],[Order_Status]]="Cancelled","Critical - Cancelled", Table1[[#This Row],[Delivery SLA Status]]="SLA Breach","Critical - Late Delivery", Table1[[#This Row],[Customer_Rating]]<3,"Attention - Low Rating", TRUE,"Normal" )} -> Critical - Cancelled | AA12: =_xlfn.XLOOKUP(Table1[[#This Row],[Customer_ID]],Customers!A:A,Customers!C:C) -> Nagpur | AB12: =TEXT(Table1[[#This Row],[Order_Date]],"mmm") -> May
A13: ORD00050 | B13: 46210 | C13: CUST061 | D13: REST010 | E13: DP003 | F13: 1232.49 | G13: 50 | H13: 206.09 | I13: 9.2 | J13: 42 | L13: Cancelled | M13: =PROPER(TRIM(L13)) -> Cancelled | N13: Wallet | O13: =TRIM(N13) -> Wallet | P13: PREMIUM10 | Q13: =TRIM(P13) -> PREMIUM10 | R13: CMP002 | S13: Restaurant delay | T13: =_xlfn.XLOOKUP(Table1[[#This Row],[Customer_ID]],Customers!A:A,Customers!B:B) -> Neha Shinde | U13: =_xlfn.XLOOKUP(Table1[[#This Row],[Restaurant_ID]],Restaurants!A:A,Restaurants!B:B) -> Dosa Junction | V13: =_xlfn.XLOOKUP(Table1[[#This Row],[Delivery_Partner_ID]],Delivery_Partners!A:A,Delivery_Partners!B:B) -> Suresh | W13: =_xlfn.XLOOKUP(Table1[[#This Row],[Campaign_ID]],Campaigns!A:A,Campaigns!B:B) -> New User Boost | X13: =Table1[[#This Row],[Order_Value]]+Table1[[#This Row],[Delivery_Fee]]-Table1[[#This Row],[Discount]] -> 1076.4 | Y13: {=_xlfn.IFS(Table1[[#This Row],[Delivery_Time_Min]]<=30,"On Time",Table1[[#This Row],[Delivery_Time_Min]]<=45,"At Risk",TRUE,"SLA Breach")} -> At Risk | Z13: {=_xlfn.IFS( Table1[[#This Row],[Order_Status]]="Cancelled","Critical - Cancelled", Table1[[#This Row],[Delivery SLA Status]]="SLA Breach","Critical - Late Delivery", Table1[[#This Row],[Customer_Rating]]<3,"Attention - Low Rating", TRUE,"Normal" )} -> Critical - Cancelled | AA13: =_xlfn.XLOOKUP(Table1[[#This Row],[Customer_ID]],Customers!A:A,Customers!C:C) -> Bengaluru | AB13: =TEXT(Table1[[#This Row],[Order_Date]],"mmm") -> Jul
A14: ORD00051 | B14: 46147 | C14: CUST011 | D14: REST009 | E14: DP003 | F14: 1439.22 | G14: 25 | H14: 197.44 | I14: 5.1 | J14: 41 | L14: Cancelled | M14: =PROPER(TRIM(L14)) -> Cancelled | N14: Credit Card | O14: =TRIM(N14) -> Credit Card | P14: WELCOME50 | Q14: =TRIM(P14) -> WELCOME50 | R14: CMP003 | S14: Delivery partner unavailable | T14: =_xlfn.XLOOKUP(Table1[[#This Row],[Customer_ID]],Customers!A:A,Customers!B:B) -> Vivaan Pawar | U14: =_xlfn.XLOOKUP(Table1[[#This Row],[Restaurant_ID]],Restaurants!A:A,Restaurants!B:B) -> Cafe Aroma | V14: =_xlfn.XLOOKUP(Table1[[#This Row],[Delivery_Partner_ID]],Delivery_Partners!A:A,Delivery_Partners!B:B) -> Suresh | W14: =_xlfn.XLOOKUP(Table1[[#This Row],[Campaign_ID]],Campaigns!A:A,Campaigns!B:B) -> Premium Treat | X14: =Table1[[#This Row],[Order_Value]]+Table1[[#This Row],[Delivery_Fee]]-Table1[[#This Row],[Discount]] -> 1266.78 | Y14: {=_xlfn.IFS(Table1[[#This Row],[Delivery_Time_Min]]<=30,"On Time",Table1[[#This Row],[Delivery_Time_Min]]<=45,"At Risk",TRUE,"SLA Breach")} -> At Risk | Z14: {=_xlfn.IFS( Table1[[#This Row],[Order_Status]]="Cancelled","Critical - Cancelled", Table1[[#This Row],[Delivery SLA Status]]="SLA Breach","Critical - Late Delivery", Table1[[#This Row],[Customer_Rating]]<3,"Attention - Low Rating", TRUE,"Normal" )} -> Critical - Cancelled | AA14: =_xlfn.XLOOKUP(Table1[[#This Row],[Customer_ID]],Customers!A:A,Customers!C:C) -> Pune | AB14: =TEXT(Table1[[#This Row],[Order_Date]],"mmm") -> May
... A52: ORD00296 | B52: 46177 | C52: CUST050 | D52: REST006 | E52: DP020 | F52: 1212.54 | G52: 40 | H52: 124.62 | I52: 9.1 | J52: 57 | L52: Cancelled | M52: =PROPER(TRIM(L52)) -> Cancelled | N52: Debit Card | O52: =TRIM(N52) -> Debit Card | P52: LUNCH15 | Q52: =TRIM(P52) -> LUNCH15 | R52: CMP001 | S52: Restaurant unavailable | T52: =_xlfn.XLOOKUP(Table1[[#This Row],[Customer_ID]],Customers!A:A,Customers!B:B) -> Akash Pawar | U52: =_xlfn.XLOOKUP(Table1[[#This Row],[Restaurant_ID]],Restaurants!A:A,Restaurants!B:B) -> Mumbai Masala | V52: =_xlfn.XLOOKUP(Table1[[#This Row],[Delivery_Partner_ID]],Delivery_Partners!A:A,Delivery_Partners!B:B) -> Mahesh | W52: =_xlfn.XLOOKUP(Table1[[#This Row],[Campaign_ID]],Campaigns!A:A,Campaigns!B:B) -> Weekend Feast | X52: =Table1[[#This Row],[Order_Value]]+Table1[[#This Row],[Delivery_Fee]]-Table1[[#This Row],[Discount]] -> 1127.92 | Y52: {=_xlfn.IFS(Table1[[#This Row],[Delivery_Time_Min]]<=30,"On Time",Table1[[#This Row],[Delivery_Time_Min]]<=45,"At Risk",TRUE,"SLA Breach")} -> SLA Breach | Z52: {=_xlfn.IFS( Table1[[#This Row],[Order_Status]]="Cancelled","Critical - Cancelled", Table1[[#This Row],[Delivery SLA Status]]="SLA Breach","Critical - Late Delivery", Table1[[#This Row],[Customer_Rating]]<3,"Attention - Low Rating", TRUE,"Normal" )} -> Critical - Cancelled | AA52: =_xlfn.XLOOKUP(Table1[[#This Row],[Customer_ID]],Customers!A:A,Customers!C:C) -> Pune | AB52: =TEXT(Table1[[#This Row],[Order_Date]],"mmm") -> Jun
A53: ORD00001 | B53: 46170 | C53: CUST049 | D53: REST014 | E53: DP015 | F53: 2038.96 | G53: 40 | H53: 0 | I53: 1.6 | J53: 22 | K53: 4 | L53: Delivered | M53: =PROPER(TRIM(L53)) -> Delivered | N53: Credit Card | O53: =TRIM(N53) -> Credit Card | P53: NONE | Q53: =TRIM(P53) -> NONE | R53: CMP007 | T53: =_xlfn.XLOOKUP(Table1[[#This Row],[Customer_ID]],Customers!A:A,Customers!B:B) -> Priya Jadhav | U53: =_xlfn.XLOOKUP(Table1[[#This Row],[Restaurant_ID]],Restaurants!A:A,Restaurants!B:B) -> Sweet Truth | V53: =_xlfn.XLOOKUP(Table1[[#This Row],[Delivery_Partner_ID]],Delivery_Partners!A:A,Delivery_Partners!B:B) -> Vivek | W53: =_xlfn.XLOOKUP(Table1[[#This Row],[Campaign_ID]],Campaigns!A:A,Campaigns!B:B) -> First Order | X53: =Table1[[#This Row],[Order_Value]]+Table1[[#This Row],[Delivery_Fee]]-Table1[[#This Row],[Discount]] -> 2078.96 | Y53: {=_xlfn.IFS(Table1[[#This Row],[Delivery_Time_Min]]<=30,"On Time",Table1[[#This Row],[Delivery_Time_Min]]<=45,"At Risk",TRUE,"SLA Breach")} -> On Time | Z53: {=_xlfn.IFS( Table1[[#This Row],[Order_Status]]="Cancelled","Critical - Cancelled", Table1[[#This Row],[Delivery SLA Status]]="SLA Breach","Critical - Late Delivery", Table1[[#This Row],[Customer_Rating]]<3,"Attention - Low Rating", TRUE,"Normal" )} -> Normal | AA53: =_xlfn.XLOOKUP(Table1[[#This Row],[Customer_ID]],Customers!A:A,Customers!C:C) -> Hyderabad | AB53: =TEXT(Table1[[#This Row],[Order_Date]],"mmm") -> May
A54: ORD00002 | B54: 46211 | C54: CUST036 | D54: REST008 | E54: DP018 | F54: 478.31 | G54: 60 | H54: 49.15 | I54: 11 | J54: 48 | K54: 5 | L54: Delivered | M54: =PROPER(TRIM(L54)) -> Delivered | N54: UPI | O54: =TRIM(N54) -> UPI | P54: BUDGET50 | Q54: =TRIM(P54) -> BUDGET50 | R54: CMP004 | T54: =_xlfn.XLOOKUP(Table1[[#This Row],[Customer_ID]],Customers!A:A,Customers!B:B) -> Sakshi Sharma | U54: =_xlfn.XLOOKUP(Table1[[#This Row],[Restaurant_ID]],Restaurants!A:A,Restaurants!B:B) -> Biryani House | V54: =_xlfn.XLOOKUP(Table1[[#This Row],[Delivery_Partner_ID]],Delivery_Partners!A:A,Delivery_Partners!B:B) -> Anil | W54: =_xlfn.XLOOKUP(Table1[[#This Row],[Campaign_ID]],Campaigns!A:A,Campaigns!B:B) -> Lunch Saver | X54: =Table1[[#This Row],[Order_Value]]+Table1[[#This Row],[Delivery_Fee]]-Table1[[#This Row],[Discount]] -> 489.16 | Y54: {=_xlfn.IFS(Table1[[#This Row],[Delivery_Time_Min]]<=30,"On Time",Table1[[#This Row],[Delivery_Time_Min]]<=45,"At Risk",TRUE,"SLA Breach")} -> SLA Breach | Z54: {=_xlfn.IFS( Table1[[#This Row],[Order_Status]]="Cancelled","Critical - Cancelled", Table1[[#This Row],[Delivery SLA Status]]="SLA Breach","Critical - Late Delivery", Table1[[#This Row],[Customer_Rating]]<3,"Attention - Low Rating", TRUE,"Normal" )} -> Critical - Late Delivery | AA54: =_xlfn.XLOOKUP(Table1[[#This Row],[Customer_ID]],Customers!A:A,Customers!C:C) -> Pune | AB54: =TEXT(Table1[[#This Row],[Order_Date]],"mmm") -> Jul
A55: ORD00003 | B55: 46191 | C55: CUST066 | D55: REST010 | E55: DP018 | F55: 1850.12 | G55: 40 | H55: 300 | I55: 5.2 | J55: 31 | K55: 5 | L55: Delivered | M55: =PROPER(TRIM(L55)) -> Delivered | N55: UPI | O55: =TRIM(N55) -> UPI | P55: SAVE100 | Q55: =TRIM(P55) -> SAVE100 | R55: CMP003 | T55: =_xlfn.XLOOKUP(Table1[[#This Row],[Customer_ID]],Customers!A:A,Customers!B:B) -> Meera Desai | U55: =_xlfn.XLOOKUP(Table1[[#This Row],[Restaurant_ID]],Restaurants!A:A,Restaurants!B:B) -> Dosa Junction | V55: =_xlfn.XLOOKUP(Table1[[#This Row],[Delivery_Partner_ID]],Delivery_Partners!A:A,Delivery_Partners!B:B) -> Anil | W55: =_xlfn.XLOOKUP(Table1[[#This Row],[Campaign_ID]],Campaigns!A:A,Campaigns!B:B) -> Premium Treat | X55: =Table1[[#This Row],[Order_Value]]+Table1[[#This Row],[Delivery_Fee]]-Table1[[#This Row],[Discount]] -> 1590.12 | Y55: {=_xlfn.IFS(Table1[[#This Row],[Delivery_Time_Min]]<=30,"On Time",Table1[[#This Row],[Delivery_Time_Min]]<=45,"At Risk",TRUE,"SLA Breach")} -> At Risk | Z55: {=_xlfn.IFS( Table1[[#This Row],[Order_Status]]="Cancelled","Critical - Cancelled", Table1[[#This Row],[Delivery SLA Status]]="SLA Breach","Critical - Late Delivery", Table1[[#This Row],[Customer_Rating]]<3,"Attention - Low Rating", TRUE,"Normal" )} -> Normal | AA55: =_xlfn.XLOOKUP(Table1[[#This Row],[Customer_ID]],Customers!A:A,Customers!C:C) -> Bengaluru | AB55: =TEXT(Table1[[#This Row],[Order_Date]],"mmm") -> Jun
A56: ORD00004 | B56: 46216 | C56: CUST001 | D56: REST021 | E56: DP016 | F56: 1279.87 | G56: 25 | H56: 0 | I56: 7.1 | J56: 40 | K56: 4.5 | L56: Delivered | M56: =PROPER(TRIM(L56)) -> Delivered | N56: Debit Card | O56: =TRIM(N56) -> Debit Card | P56: NONE | Q56: =TRIM(P56) -> NONE | R56: CMP007 | T56: =_xlfn.XLOOKUP(Table1[[#This Row],[Customer_ID]],Customers!A:A,Customers!B:B) -> Neha Kulkarni | U56: =_xlfn.XLOOKUP(Table1[[#This Row],[Restaurant_ID]],Restaurants!A:A,Restaurants!B:B) -> Grill House | V56: =_xlfn.XLOOKUP(Table1[[#This Row],[Delivery_Partner_ID]],Delivery_Partners!A:A,Delivery_Partners!B:B) -> Rohit | W56: =_xlfn.XLOOKUP(Table1[[#This Row],[Campaign_ID]],Campaigns!A:A,Campaigns!B:B) -> First Order | X56: =Table1[[#This Row],[Order_Value]]+Table1[[#This Row],[Delivery_Fee]]-Table1[[#This Row],[Discount]] -> 1304.87 | Y56: {=_xlfn.IFS(Table1[[#This Row],[Delivery_Time_Min]]<=30,"On Time",Table1[[#This Row],[Delivery_Time_Min]]<=45,"At Risk",TRUE,"SLA Breach")} -> At Risk | Z56: {=_xlfn.IFS( Table1[[#This Row],[Order_Status]]="Cancelled","Critical - Cancelled", Table1[[#This Row],[Delivery SLA Status]]="SLA Breach","Critical - Late Delivery", Table1[[#This Row],[Customer_Rating]]<3,"Attention - Low Rating", TRUE,"Normal" )} -> Normal | AA56: =_xlfn.XLOOKUP(Table1[[#This Row],[Customer_ID]],Customers!A:A,Customers!C:C) -> Nagpur | AB56: =TEXT(Table1[[#This Row],[Order_Date]],"mmm") -> Jul
A57: ORD00006 | B57: 46206 | C57: CUST050 | D57: REST012 | E57: DP001 | F57: 1364.64 | G57: 35 | H57: 259.08 | I57: 8 | J57: 49 | K57: 5 | L57: Delivered | M57: =PROPER(TRIM(L57)) -> Delivered | N57: Credit Card | O57: =TRIM(N57) -> Credit Card | P57: LUNCH15 | Q57: =TRIM(P57) -> LUNCH15 | R57: CMP006 | T57: =_xlfn.XLOOKUP(Table1[[#This Row],[Customer_ID]],Customers!A:A,Customers!B:B) -> Akash Pawar | U57: =_xlfn.XLOOKUP(Table1[[#This Row],[Restaurant_ID]],Restaurants!A:A,Restaurants!B:B) -> Pizza Craft | V57: =_xlfn.XLOOKUP(Table1[[#This Row],[Delivery_Partner_ID]],Delivery_Partners!A:A,Delivery_Partners!B:B) -> Rahul | W57: =_xlfn.XLOOKUP(Table1[[#This Row],[Campaign_ID]],Campaigns!A:A,Campaigns!B:B) -> Festival Special | X57: =Table1[[#This Row],[Order_Value]]+Table1[[#This Row],[Delivery_Fee]]-Table1[[#This Row],[Discount]] -> 1140.56 | Y57: {=_xlfn.IFS(Table1[[#This Row],[Delivery_Time_Min]]<=30,"On Time",Table1[[#This Row],[Delivery_Time_Min]]<=45,"At Risk",TRUE,"SLA Breach")} -> SLA Breach | Z57: {=_xlfn.IFS( Table1[[#This Row],[Order_Status]]="Cancelled","Critical - Cancelled", Table1[[#This Row],[Delivery SLA Status]]="SLA Breach","Critical - Late Delivery", Table1[[#This Row],[Customer_Rating]]<3,"Attention - Low Rating", TRUE,"Normal" )} -> Critical - Late Delivery | AA57: =_xlfn.XLOOKUP(Table1[[#This Row],[Customer_ID]],Customers!A:A,Customers!C:C) -> Pune | AB57: =TEXT(Table1[[#This Row],[Order_Date]],"mmm") -> Jul
A58: ORD00007 | B58: 46223 | C58: CUST038 | D58: REST018 | E58: DP002 | F58: 673.86 | G58: 40 | H58: 102.4 | I58: 9.6 | J58: 28 | K58: 4.5 | L58: Delivered | M58: =PROPER(TRIM(L58)) -> Delivered | N58: Wallet | O58: =TRIM(N58) -> Wallet | P58: LUNCH15 | Q58: =TRIM(P58) -> LUNCH15 | R58: CMP002 | T58: =_xlfn.XLOOKUP(Table1[[#This Row],[Customer_ID]],Customers!A:A,Customers!B:B) -> Aditya Desai | U58: =_xlfn.XLOOKUP(Table1[[#This Row],[Restaurant_ID]],Restaurants!A:A,Restaurants!B:B) -> South Spice | V58: =_xlfn.XLOOKUP(Table1[[#This Row],[Delivery_Partner_ID]],Delivery_Partners!A:A,Delivery_Partners!B:B) -> Amit | W58: =_xlfn.XLOOKUP(Table1[[#This Row],[Campaign_ID]],Campaigns!A:A,Campaigns!B:B) -> New User Boost | X58: =Table1[[#This Row],[Order_Value]]+Table1[[#This Row],[Delivery_Fee]]-Table1[[#This Row],[Discount]] -> 611.46 | Y58: {=_xlfn.IFS(Table1[[#This Row],[Delivery_Time_Min]]<=30,"On Time",Table1[[#This Row],[Delivery_Time_Min]]<=45,"At Risk",TRUE,"SLA Breach")} -> On Time | Z58: {=_xlfn.IFS( Table1[[#This Row],[Order_Status]]="Cancelled","Critical - Cancelled", Table1[[#This Row],[Delivery SLA Status]]="SLA Breach","Critical - Late Delivery", Table1[[#This Row],[Customer_Rating]]<3,"Attention - Low Rating", TRUE,"Normal" )} -> Normal | AA58: =_xlfn.XLOOKUP(Table1[[#This Row],[Customer_ID]],Customers!A:A,Customers!C:C) -> Mumbai | AB58: =TEXT(Table1[[#This Row],[Order_Date]],"mmm") -> Jul
A59: ORD00010 | B59: 46143 | C59: CUST005 | D59: REST009 | E59: DP012 | F59: 662.87 | G59: 20 | H59: 116.86 | I59: 6.6 | J59: 29 | K59: 4 | L59: Delivered | M59: =PROPER(TRIM(L59)) -> Delivered | N59: Debit Card | O59: =TRIM(N59) -> Debit Card | P59: PREMIUM10 | Q59: =TRIM(P59) -> PREMIUM10 | R59: CMP002 | T59: =_xlfn.XLOOKUP(Table1[[#This Row],[Customer_ID]],Customers!A:A,Customers!B:B) -> Isha Gupta | U59: =_xlfn.XLOOKUP(Table1[[#This Row],[Restaurant_ID]],Restaurants!A:A,Restaurants!B:B) -> Cafe Aroma | V59: =_xlfn.XLOOKUP(Table1[[#This Row],[Delivery_Partner_ID]],Delivery_Partners!A:A,Delivery_Partners!B:B) -> Manoj | W59: =_xlfn.XLOOKUP(Table1[[#This Row],[Campaign_ID]],Campaigns!A:A,Campaigns!B:B) -> New User Boost | X59: =Table1[[#This Row],[Order_Value]]+Table1[[#This Row],[Delivery_Fee]]-Table1[[#This Row],[Discount]] -> 566.01 | Y59: {=_xlfn.IFS(Table1[[#This Row],[Delivery_Time_Min]]<=30,"On Time",Table1[[#This Row],[Delivery_Time_Min]]<=45,"At Risk",TRUE,"SLA Breach")} -> On Time | Z59: {=_xlfn.IFS( Table1[[#This Row],[Order_Status]]="Cancelled","Critical - Cancelled", Table1[[#This Row],[Delivery SLA Status]]="SLA Breach","Critical - Late Delivery", Table1[[#This Row],[Customer_Rating]]<3,"Attention - Low Rating", TRUE,"Normal" )} -> Normal | AA59: =_xlfn.XLOOKUP(Table1[[#This Row],[Customer_ID]],Customers!A:A,Customers!C:C) -> Bengaluru | AB59: =TEXT(Table1[[#This Row],[Order_Date]],"mmm") -> May
A60: ORD00013 | B60: 46184 | C60: CUST013 | D60: REST020 | E60: DP004 | F60: 1142.75 | G60: 20 | H60: 185.31 | I60: 9.2 | J60: 52 | K60: 4.5 | L60: Delivered | M60: =PROPER(TRIM(L60)) -> Delivered | N60: Wallet | O60: =TRIM(N60) -> Wallet | P60: PREMIUM10 | Q60: =TRIM(P60) -> PREMIUM10 | R60: CMP002 | T60: =_xlfn.XLOOKUP(Table1[[#This Row],[Customer_ID]],Customers!A:A,Customers!B:B) -> Sakshi More | U60: =_xlfn.XLOOKUP(Table1[[#This Row],[Restaurant_ID]],Restaurants!A:A,Restaurants!B:B) -> Wrap Street | V60: =_xlfn.XLOOKUP(Table1[[#This Row],[Delivery_Partner_ID]],Delivery_Partners!A:A,Delivery_Partners!B:B) -> Vikas | W60: =_xlfn.XLOOKUP(Table1[[#This Row],[Campaign_ID]],Campaigns!A:A,Campaigns!B:B) -> New User Boost | X60: =Table1[[#This Row],[Order_Value]]+Table1[[#This Row],[Delivery_Fee]]-Table1[[#This Row],[Discount]] -> 977.44 | Y60: {=_xlfn.IFS(Table1[[#This Row],[Delivery_Time_Min]]<=30,"On Time",Table1[[#This Row],[Delivery_Time_Min]]<=45,"At Risk",TRUE,"SLA Breach")} -> SLA Breach | Z60: {=_xlfn.IFS( Table1[[#This Row],[Order_Status]]="Cancelled","Critical - Cancelled", Table1[[#This Row],[Delivery SLA Status]]="SLA Breach","Critical - Late Delivery", Table1[[#This Row],[Customer_Rating]]<3,"Attention - Low Rating", TRUE,"Normal" )} -> Critical - Late Delivery | AA60: =_xlfn.XLOOKUP(Table1[[#This Row],[Customer_ID]],Customers!A:A,Customers!C:C) -> Bengaluru | AB60: =TEXT(Table1[[#This Row],[Order_Date]],"mmm") -> Jun
A61: ORD00015 | B61: 46199 | C61: CUST036 | D61: REST024 | E61: DP006 | F61: 1594.09 | G61: 25 | H61: 0 | I61: 6.4 | J61: 37 | K61: 4.5 | L61: Delivered | M61: =PROPER(TRIM(L61)) -> Delivered | N61: Debit Card | O61: =TRIM(N61) -> Debit Card | P61: NONE | Q61: =TRIM(P61) -> NONE | R61: CMP002 | T61: =_xlfn.XLOOKUP(Table1[[#This Row],[Customer_ID]],Customers!A:A,Customers!B:B) -> Sakshi Sharma | U61: =_xlfn.XLOOKUP(Table1[[#This Row],[Restaurant_ID]],Restaurants!A:A,Restaurants!B:B) -> Pasta Point | V61: =_xlfn.XLOOKUP(Table1[[#This Row],[Delivery_Partner_ID]],Delivery_Partners!A:A,Delivery_Partners!B:B) -> Kunal | W61: =_xlfn.XLOOKUP(Table1[[#This Row],[Campaign_ID]],Campaigns!A:A,Campaigns!B:B) -> New User Boost | X61: =Table1[[#This Row],[Order_Value]]+Table1[[#This Row],[Delivery_Fee]]-Table1[[#This Row],[Discount]] -> 1619.09 | Y61: {=_xlfn.IFS(Table1[[#This Row],[Delivery_Time_Min]]<=30,"On Time",Table1[[#This Row],[Delivery_Time_Min]]<=45,"At Risk",TRUE,"SLA Breach")} -> At Risk | Z61: {=_xlfn.IFS( Table1[[#This Row],[Order_Status]]="Cancelled","Critical - Cancelled", Table1[[#This Row],[Delivery SLA Status]]="SLA Breach","Critical - Late Delivery", Table1[[#This Row],[Customer_Rating]]<3,"Attention - Low Rating", TRUE,"Normal" )} -> Normal | AA61: =_xlfn.XLOOKUP(Table1[[#This Row],[Customer_ID]],Customers!A:A,Customers!C:C) -> Pune | AB61: =TEXT(Table1[[#This Row],[Order_Date]],"mmm") -> Jun
A62: ORD00016 | B62: 46153 | C62: CUST008 | D62: REST019 | E62: DP013 | F62: 764.88 | G62: 60 | H62: 136.92 | I62: 9.4 | J62: 47 | K62: 4.5 | L62: Delivered | M62: =PROPER(TRIM(L62)) -> Delivered | N62: Cash on Delivery | O62: =TRIM(N62) -> Cash on Delivery | P62: PREMIUM10 | Q62: =TRIM(P62) -> PREMIUM10 | R62: CMP004 | T62: =_xlfn.XLOOKUP(Table1[[#This Row],[Customer_ID]],Customers!A:A,Customers!B:B) -> Yash Kulkarni | U62: =_xlfn.XLOOKUP(Table1[[#This Row],[Restaurant_ID]],Restaurants!A:A,Restaurants!B:B) -> The Breakfast Club | V62: =_xlfn.XLOOKUP(Table1[[#This Row],[Delivery_Partner_ID]],Delivery_Partners!A:A,Delivery_Partners!B:B) -> Deepak | W62: =_xlfn.XLOOKUP(Table1[[#This Row],[Campaign_ID]],Campaigns!A:A,Campaigns!B:B) -> Lunch Saver | X62: =Table1[[#This Row],[Order_Value]]+Table1[[#This Row],[Delivery_Fee]]-Table1[[#This Row],[Discount]] -> 687.96 | Y62: {=_xlfn.IFS(Table1[[#This Row],[Delivery_Time_Min]]<=30,"On Time",Table1[[#This Row],[Delivery_Time_Min]]<=45,"At Risk",TRUE,"SLA Breach")} -> SLA Breach | Z62: {=_xlfn.IFS( Table1[[#This Row],[Order_Status]]="Cancelled","Critical - Cancelled", Table1[[#This Row],[Delivery SLA Status]]="SLA Breach","Critical - Late Delivery", Table1[[#This Row],[Customer_Rating]]<3,"Attention - Low Rating", TRUE,"Normal" )} -> Critical - Late Delivery | AA62: =_xlfn.XLOOKUP(Table1[[#This Row],[Customer_ID]],Customers!A:A,Customers!C:C) -> Nagpur | AB62: =TEXT(Table1[[#This Row],[Order_Date]],"mmm") -> May
A63: ORD00017 | B63: 46215 | C63: CUST077 | D63: REST011 | E63: DP003 | F63: 823.62 | G63: 20 | H63: 89.15 | I63: 8.5 | J63: 26 | K63: 4 | L63: Delivered | M63: =PROPER(TRIM(L63)) -> Delivered | N63: UPI | O63: =TRIM(N63) -> UPI | P63: PREMIUM10 | Q63: =TRIM(P63) -> PREMIUM10 | R63: CMP001 | T63: =_xlfn.XLOOKUP(Table1[[#This Row],[Customer_ID]],Customers!A:A,Customers!B:B) -> Aarav More | U63: =_xlfn.XLOOKUP(Table1[[#This Row],[Restaurant_ID]],Restaurants!A:A,Restaurants!B:B) -> Wok Express | V63: =_xlfn.XLOOKUP(Table1[[#This Row],[Delivery_Partner_ID]],Delivery_Partners!A:A,Delivery_Partners!B:B) -> Suresh | W63: =_xlfn.XLOOKUP(Table1[[#This Row],[Campaign_ID]],Campaigns!A:A,Campaigns!B:B) -> Weekend Feast | X63: =Table1[[#This Row],[Order_Value]]+Table1[[#This Row],[Delivery_Fee]]-Table1[[#This Row],[Discount]] -> 754.47 | Y63: {=_xlfn.IFS(Table1[[#This Row],[Delivery_Time_Min]]<=30,"On Time",Table1[[#This Row],[Delivery_Time_Min]]<=45,"At Risk",TRUE,"SLA Breach")} -> On Time | Z63: {=_xlfn.IFS( Table1[[#This Row],[Order_Status]]="Cancelled","Critical - Cancelled", Table1[[#This Row],[Delivery SLA Status]]="SLA Breach","Critical - Late Delivery", Table1[[#This Row],[Customer_Rating]]<3,"Attention - Low Rating", TRUE,"Normal" )} -> Normal | AA63: =_xlfn.XLOOKUP(Table1[[#This Row],[Customer_ID]],Customers!A:A,Customers!C:C) -> Bengaluru | AB63: =TEXT(Table1[[#This Row],[Order_Date]],"mmm") -> Jul
A64: ORD00018 | B64: 46218 | C64: CUST075 | D64: REST015 | E64: DP006 | F64: 1045.6 | G64: 30 | H64: 143.45 | I64: 11.3 | J64: 47 | L64: delivered | M64: =PROPER(TRIM(L64)) -> Delivered | N64: Debit Card | O64: =TRIM(N64) -> Debit Card | P64: MONSOON20 | Q64: =TRIM(P64) -> MONSOON20 | R64: CMP007 | S64: Customer changed mind | T64: =_xlfn.XLOOKUP(Table1[[#This Row],[Customer_ID]],Customers!A:A,Customers!B:B) -> Rahul Jadhav | U64: =_xlfn.XLOOKUP(Table1[[#This Row],[Restaurant_ID]],Restaurants!A:A,Restaurants!B:B) -> Royal Thali | V64: =_xlfn.XLOOKUP(Table1[[#This Row],[Delivery_Partner_ID]],Delivery_Partners!A:A,Delivery_Partners!B:B) -> Kunal | W64: =_xlfn.XLOOKUP(Table1[[#This Row],[Campaign_ID]],Campaigns!A:A,Campaigns!B:B) -> First Order | X64: =Table1[[#This Row],[Order_Value]]+Table1[[#This Row],[Delivery_Fee]]-Table1[[#This Row],[Discount]] -> 932.15 | Y64: {=_xlfn.IFS(Table1[[#This Row],[Delivery_Time_Min]]<=30,"On Time",Table1[[#This Row],[Delivery_Time_Min]]<=45,"At Risk",TRUE,"SLA Breach")} -> SLA Breach | Z64: {=_xlfn.IFS( Table1[[#This Row],[Order_Status]]="Cancelled","Critical - Cancelled", Table1[[#This Row],[Delivery SLA Status]]="SLA Breach","Critical - Late Delivery", Table1[[#This Row],[Customer_Rating]]<3,"Attention - Low Rating", TRUE,"Normal" )} -> Critical - Late Delivery | AA64: =_xlfn.XLOOKUP(Table1[[#This Row],[Customer_ID]],Customers!A:A,Customers!C:C) -> Pune | AB64: =TEXT(Table1[[#This Row],[Order_Date]],"mmm") -> Jul
A65: ORD00020 | B65: 46208 | C65: CUST042 | D65: REST025 | E65: DP018 | F65: 2305.95 | G65: 50 | H65: 300 | I65: 5.8 | J65: 32 | K65: 3.5 | L65: Delivered | M65: =PROPER(TRIM(L65)) -> Delivered | N65: Wallet | O65: =TRIM(N65) -> Wallet | P65: FESTIVE25 | Q65: =TRIM(P65) -> FESTIVE25 | R65: CMP008 | T65: =_xlfn.XLOOKUP(Table1[[#This Row],[Customer_ID]],Customers!A:A,Customers!B:B) -> Aarav Joshi | U65: =_xlfn.XLOOKUP(Table1[[#This Row],[Restaurant_ID]],Restaurants!A:A,Restaurants!B:B) -> Tandoor Tales | V65: =_xlfn.XLOOKUP(Table1[[#This Row],[Delivery_Partner_ID]],Delivery_Partners!A:A,Delivery_Partners!B:B) -> Anil | W65: =_xlfn.XLOOKUP(Table1[[#This Row],[Campaign_ID]],Campaigns!A:A,Campaigns!B:B) -> Monsoon Meals | X65: =Table1[[#This Row],[Order_Value]]+Table1[[#This Row],[Delivery_Fee]]-Table1[[#This Row],[Discount]] -> 2055.95 | Y65: {=_xlfn.IFS(Table1[[#This Row],[Delivery_Time_Min]]<=30,"On Time",Table1[[#This Row],[Delivery_Time_Min]]<=45,"At Risk",TRUE,"SLA Breach")} -> At Risk | Z65: {=_xlfn.IFS( Table1[[#This Row],[Order_Status]]="Cancelled","Critical - Cancelled", Table1[[#This Row],[Delivery SLA Status]]="SLA Breach","Critical - Late Delivery", Table1[[#This Row],[Customer_Rating]]<3,"Attention - Low Rating", TRUE,"Normal" )} -> Normal | AA65: =_xlfn.XLOOKUP(Table1[[#This Row],[Customer_ID]],Customers!A:A,Customers!C:C) -> Nagpur | AB65: =TEXT(Table1[[#This Row],[Order_Date]],"mmm") -> Jul
A66: ORD00021 | B66: 46169 | C66: CUST051 | D66: REST007 | E66: DP019 | F66: 1230.17 | G66: 35 | H66: 235.16 | I66: 7.8 | J66: 43 | K66: 4.5 | L66: Delivered | M66: =PROPER(TRIM(L66)) -> Delivered | N66: Wallet | O66: =TRIM(N66) -> Wallet | P66: SAVE100 | Q66: =TRIM(P66) -> SAVE100 | R66: CMP006 | T66: =_xlfn.XLOOKUP(Table1[[#This Row],[Customer_ID]],Customers!A:A,Customers!B:B) -> Amit Desai | U66: =_xlfn.XLOOKUP(Table1[[#This Row],[Restaurant_ID]],Restaurants!A:A,Restaurants!B:B) -> Pune Bites | V66: =_xlfn.XLOOKUP(Table1[[#This Row],[Delivery_Partner_ID]],Delivery_Partners!A:A,Delivery_Partners!B:B) -> Ajay | W66: =_xlfn.XLOOKUP(Table1[[#This Row],[Campaign_ID]],Campaigns!A:A,Campaigns!B:B) -> Festival Special | X66: =Table1[[#This Row],[Order_Value]]+Table1[[#This Row],[Delivery_Fee]]-Table1[[#This Row],[Discount]] -> 1030.01 | Y66: {=_xlfn.IFS(Table1[[#This Row],[Delivery_Time_Min]]<=30,"On Time",Table1[[#This Row],[Delivery_Time_Min]]<=45,"At Risk",TRUE,"SLA Breach")} -> At Risk | Z66: {=_xlfn.IFS( Table1[[#This Row],[Order_Status]]="Cancelled","Critical - Cancelled", Table1[[#This Row],[Delivery SLA Status]]="SLA Breach","Critical - Late Delivery", Table1[[#This Row],[Customer_Rating]]<3,"Attention - Low Rating", TRUE,"Normal" )} -> Normal | AA66: =_xlfn.XLOOKUP(Table1[[#This Row],[Customer_ID]],Customers!A:A,Customers!C:C) -> Nagpur | AB66: =TEXT(Table1[[#This Row],[Order_Date]],"mmm") -> May
A67: ORD00022 | B67: 46155 | C67: CUST038 | D67: REST025 | E67: DP001 | F67: 1615.01 | G67: 60 | H67: 300 | I67: 10.6 | J67: 39 | K67: 3 | L67: Delivered | M67: =PROPER(TRIM(L67)) -> Delivered | N67: Cash on Delivery | O67: =TRIM(N67) -> Cash on Delivery | P67: FESTIVE25 | Q67: =TRIM(P67) -> FESTIVE25 | R67: CMP005 | T67: =_xlfn.XLOOKUP(Table1[[#This Row],[Customer_ID]],Customers!A:A,Customers!B:B) -> Aditya Desai | U67: =_xlfn.XLOOKUP(Table1[[#This Row],[Restaurant_ID]],Restaurants!A:A,Restaurants!B:B) -> Tandoor Tales | V67: =_xlfn.XLOOKUP(Table1[[#This Row],[Delivery_Partner_ID]],Delivery_Partners!A:A,Delivery_Partners!B:B) -> Rahul | W67: =_xlfn.XLOOKUP(Table1[[#This Row],[Campaign_ID]],Campaigns!A:A,Campaigns!B:B) -> Budget Bites | X67: =Table1[[#This Row],[Order_Value]]+Table1[[#This Row],[Delivery_Fee]]-Table1[[#This Row],[Discount]] -> 1375.01 | Y67: {=_xlfn.IFS(Table1[[#This Row],[Delivery_Time_Min]]<=30,"On Time",Table1[[#This Row],[Delivery_Time_Min]]<=45,"At Risk",TRUE,"SLA Breach")} -> At Risk | Z67: {=_xlfn.IFS( Table1[[#This Row],[Order_Status]]="Cancelled","Critical - Cancelled", Table1[[#This Row],[Delivery SLA Status]]="SLA Breach","Critical - Late Delivery", Table1[[#This Row],[Customer_Rating]]<3,"Attention - Low Rating", TRUE,"Normal" )} -> Normal | AA67: =_xlfn.XLOOKUP(Table1[[#This Row],[Customer_ID]],Customers!A:A,Customers!C:C) -> Mumbai | AB67: =TEXT(Table1[[#This Row],[Order_Date]],"mmm") -> May
A68: ORD00023 | B68: 46185 | C68: CUST052 | D68: REST024 | E68: DP015 | F68: 727.41 | G68: 30 | H68: 59.44 | I68: 7.6 | J68: 60 | K68: 4.5 | L68: Delivered | M68: =PROPER(TRIM(L68)) -> Delivered | N68: Wallet | O68: =TRIM(N68) -> Wallet | P68: MONSOON20 | Q68: =TRIM(P68) -> MONSOON20 | R68: CMP005 | T68: =_xlfn.XLOOKUP(Table1[[#This Row],[Customer_ID]],Customers!A:A,Customers!B:B) -> Aarav Sharma | U68: =_xlfn.XLOOKUP(Table1[[#This Row],[Restaurant_ID]],Restaurants!A:A,Restaurants!B:B) -> Pasta Point | V68: =_xlfn.XLOOKUP(Table1[[#This Row],[Delivery_Partner_ID]],Delivery_Partners!A:A,Delivery_Partners!B:B) -> Vivek | W68: =_xlfn.XLOOKUP(Table1[[#This Row],[Campaign_ID]],Campaigns!A:A,Campaigns!B:B) -> Budget Bites | X68: =Table1[[#This Row],[Order_Value]]+Table1[[#This Row],[Delivery_Fee]]-Table1[[#This Row],[Discount]] -> 697.97 | Y68: {=_xlfn.IFS(Table1[[#This Row],[Delivery_Time_Min]]<=30,"On Time",Table1[[#This Row],[Delivery_Time_Min]]<=45,"At Risk",TRUE,"SLA Breach")} -> SLA Breach | Z68: {=_xlfn.IFS( Table1[[#This Row],[Order_Status]]="Cancelled","Critical - Cancelled", Table1[[#This Row],[Delivery SLA Status]]="SLA Breach","Critical - Late Delivery", Table1[[#This Row],[Customer_Rating]]<3,"Attention - Low Rating", TRUE,"Normal" )} -> Critical - Late Delivery | AA68: =_xlfn.XLOOKUP(Table1[[#This Row],[Customer_ID]],Customers!A:A,Customers!C:C) -> Pune | AB68: =TEXT(Table1[[#This Row],[Order_Date]],"mmm") -> Jun
A69: ORD00025 | B69: 46163 | C69: CUST043 | D69: REST012 | E69: DP012 | F69: 879.64 | G69: 25 | H69: 83.21 | I69: 10.2 | J69: 53 | K69: 3.5 | L69: Delivered | M69: =PROPER(TRIM(L69)) -> Delivered | N69: Cash on Delivery | O69: =TRIM(N69) -> Cash on Delivery | P69: WELCOME50 | Q69: =TRIM(P69) -> WELCOME50 | R69: CMP004 | T69: =_xlfn.XLOOKUP(Table1[[#This Row],[Customer_ID]],Customers!A:A,Customers!B:B) -> Sneha Desai | U69: =_xlfn.XLOOKUP(Table1[[#This Row],[Restaurant_ID]],Restaurants!A:A,Restaurants!B:B) -> Pizza Craft | V69: =_xlfn.XLOOKUP(Table1[[#This Row],[Delivery_Partner_ID]],Delivery_Partners!A:A,Delivery_Partners!B:B) -> Manoj | W69: =_xlfn.XLOOKUP(Table1[[#This Row],[Campaign_ID]],Campaigns!A:A,Campaigns!B:B) -> Lunch Saver | X69: =Table1[[#This Row],[Order_Value]]+Table1[[#This Row],[Delivery_Fee]]-Table1[[#This Row],[Discount]] -> 821.43 | Y69: {=_xlfn.IFS(Table1[[#This Row],[Delivery_Time_Min]]<=30,"On Time",Table1[[#This Row],[Delivery_Time_Min]]<=45,"At Risk",TRUE,"SLA Breach")} -> SLA Breach | Z69: {=_xlfn.IFS( Table1[[#This Row],[Order_Status]]="Cancelled","Critical - Cancelled", Table1[[#This Row],[Delivery SLA Status]]="SLA Breach","Critical - Late Delivery", Table1[[#This Row],[Customer_Rating]]<3,"Attention - Low Rating", TRUE,"Normal" )} -> Critical - Late Delivery | AA69: =_xlfn.XLOOKUP(Table1[[#This Row],[Customer_ID]],Customers!A:A,Customers!C:C) -> Hyderabad | AB69: =TEXT(Table1[[#This Row],[Order_Date]],"mmm") -> May
A70: ORD00027 | B70: 46167 | C70: CUST063 | D70: REST020 | E70: DP011 | F70: 641.09 | G70: 60 | H70: 71.45 | I70: 6 | J70: 26 | K70: 4 | L70: Delivered | M70: =PROPER(TRIM(L70)) -> Delivered | N70: Cash on Delivery | O70: =TRIM(N70) -> Cash on Delivery | P70: LUNCH15 | Q70: =TRIM(P70) -> LUNCH15 | R70: CMP006 | T70: =_xlfn.XLOOKUP(Table1[[#This Row],[Customer_ID]],Customers!A:A,Customers!B:B) -> Tanvi Kulkarni | U70: =_xlfn.XLOOKUP(Table1[[#This Row],[Restaurant_ID]],Restaurants!A:A,Restaurants!B:B) -> Wrap Street | V70: =_xlfn.XLOOKUP(Table1[[#This Row],[Delivery_Partner_ID]],Delivery_Partners!A:A,Delivery_Partners!B:B) -> Prakash | W70: =_xlfn.XLOOKUP(Table1[[#This Row],[Campaign_ID]],Campaigns!A:A,Campaigns!B:B) -> Festival Special | X70: =Table1[[#This Row],[Order_Value]]+Table1[[#This Row],[Delivery_Fee]]-Table1[[#This Row],[Discount]] -> 629.64 | Y70: {=_xlfn.IFS(Table1[[#This Row],[Delivery_Time_Min]]<=30,"On Time",Table1[[#This Row],[Delivery_Time_Min]]<=45,"At Risk",TRUE,"SLA Breach")} -> On Time | Z70: {=_xlfn.IFS( Table1[[#This Row],[Order_Status]]="Cancelled","Critical - Cancelled", Table1[[#This Row],[Delivery SLA Status]]="SLA Breach","Critical - Late Delivery", Table1[[#This Row],[Customer_Rating]]<3,"Attention - Low Rating", TRUE,"Normal" )} -> Normal | AA70: =_xlfn.XLOOKUP(Table1[[#This Row],[Customer_ID]],Customers!A:A,Customers!C:C) -> Pune | AB70: =TEXT(Table1[[#This Row],[Order_Date]],"mmm") -> May
A71: ORD00029 | B71: 46172 | C71: CUST063 | D71: REST008 | E71: DP017 | F71: 850.37 | G71: 30 | H71: 174.94 | I71: 3.3 | J71: 31 | K71: 2.5 | L71: Delivered | M71: =PROPER(TRIM(L71)) -> Delivered | N71: Credit Card | O71: =TRIM(N71) -> Credit Card | P71: SAVE100 | Q71: =TRIM(P71) -> SAVE100 | R71: CMP007 | T71: =_xlfn.XLOOKUP(Table1[[#This Row],[Customer_ID]],Customers!A:A,Customers!B:B) -> Tanvi Kulkarni | U71: =_xlfn.XLOOKUP(Table1[[#This Row],[Restaurant_ID]],Restaurants!A:A,Restaurants!B:B) -> Biryani House | V71: =_xlfn.XLOOKUP(Table1[[#This Row],[Delivery_Partner_ID]],Delivery_Partners!A:A,Delivery_Partners!B:B) -> Sanjay | W71: =_xlfn.XLOOKUP(Table1[[#This Row],[Campaign_ID]],Campaigns!A:A,Campaigns!B:B) -> First Order | X71: =Table1[[#This Row],[Order_Value]]+Table1[[#This Row],[Delivery_Fee]]-Table1[[#This Row],[Discount]] -> 705.43 | Y71: {=_xlfn.IFS(Table1[[#This Row],[Delivery_Time_Min]]<=30,"On Time",Table1[[#This Row],[Delivery_Time_Min]]<=45,"At Risk",TRUE,"SLA Breach")} -> At Risk | Z71: {=_xlfn.IFS( Table1[[#This Row],[Order_Status]]="Cancelled","Critical - Cancelled", Table1[[#This Row],[Delivery SLA Status]]="SLA Breach","Critical - Late Delivery", Table1[[#This Row],[Customer_Rating]]<3,"Attention - Low Rating", TRUE,"Normal" )} -> Attention - Low Rating | AA71: =_xlfn.XLOOKUP(Table1[[#This Row],[Customer_ID]],Customers!A:A,Customers!C:C) -> Pune | AB71: =TEXT(Table1[[#This Row],[Order_Date]],"mmm") -> May
A72: ORD00031 | B72: 46209 | C72: CUST032 | D72: REST010 | E72: DP010 | F72: 697.04 | G72: 60 | H72: 125.63 | I72: 8.2 | J72: 52 | K72: 4.5 | L72: Delivered | M72: =PROPER(TRIM(L72)) -> Delivered | N72: Debit Card | O72: =TRIM(N72) -> Debit Card | P72: SAVE100 | Q72: =TRIM(P72) -> SAVE100 | R72: CMP003 | T72: =_xlfn.XLOOKUP(Table1[[#This Row],[Customer_ID]],Customers!A:A,Customers!B:B) -> Tanvi Patil | U72: =_xlfn.XLOOKUP(Table1[[#This Row],[Restaurant_ID]],Restaurants!A:A,Restaurants!B:B) -> Dosa Junction | V72: =_xlfn.XLOOKUP(Table1[[#This Row],[Delivery_Partner_ID]],Delivery_Partners!A:A,Delivery_Partners!B:B) -> Nitin | W72: =_xlfn.XLOOKUP(Table1[[#This Row],[Campaign_ID]],Campaigns!A:A,Campaigns!B:B) -> Premium Treat | X72: =Table1[[#This Row],[Order_Value]]+Table1[[#This Row],[Delivery_Fee]]-Table1[[#This Row],[Discount]] -> 631.41 | Y72: {=_xlfn.IFS(Table1[[#This Row],[Delivery_Time_Min]]<=30,"On Time",Table1[[#This Row],[Delivery_Time_Min]]<=45,"At Risk",TRUE,"SLA Breach")} -> SLA Breach | Z72: {=_xlfn.IFS( Table1[[#This Row],[Order_Status]]="Cancelled","Critical - Cancelled", Table1[[#This Row],[Delivery SLA Status]]="SLA Breach","Critical - Late Delivery", Table1[[#This Row],[Customer_Rating]]<3,"Attention - Low Rating", TRUE,"Normal" )} -> Critical - Late Delivery | AA72: =_xlfn.XLOOKUP(Table1[[#This Row],[Customer_ID]],Customers!A:A,Customers!C:C) -> Bengaluru | AB72: =TEXT(Table1[[#This Row],[Order_Date]],"mmm") -> Jul
A73: ORD00033 | B73: 46202 | C73: CUST037 | D73: REST022 | E73: DP014 | F73: 879.33 | G73: 25 | H73: 174.76 | I73: 2.4 | J73: 27 | K73: 4.5 | L73: Delivered | M73: =PROPER(TRIM(L73)) -> Delivered | N73: Credit Card | O73: =TRIM(N73) -> Credit Card | P73: MONSOON20 | Q73: =TRIM(P73) -> MONSOON20 | R73: CMP007 | T73: =_xlfn.XLOOKUP(Table1[[#This Row],[Customer_ID]],Customers!A:A,Customers!B:B) -> Aditya Kulkarni | U73: =_xlfn.XLOOKUP(Table1[[#This Row],[Restaurant_ID]],Restaurants!A:A,Restaurants!B:B) -> Chinese Wok | V73: =_xlfn.XLOOKUP(Table1[[#This Row],[Delivery_Partner_ID]],Delivery_Partners!A:A,Delivery_Partners!B:B) -> Arjun | W73: =_xlfn.XLOOKUP(Table1[[#This Row],[Campaign_ID]],Campaigns!A:A,Campaigns!B:B) -> First Order | X73: =Table1[[#This Row],[Order_Value]]+Table1[[#This Row],[Delivery_Fee]]-Table1[[#This Row],[Discount]] -> 729.57 | Y73: {=_xlfn.IFS(Table1[[#This Row],[Delivery_Time_Min]]<=30,"On Time",Table1[[#This Row],[Delivery_Time_Min]]<=45,"At Risk",TRUE,"SLA Breach")} -> On Time | Z73: {=_xlfn.IFS( Table1[[#This Row],[Order_Status]]="Cancelled","Critical - Cancelled", Table1[[#This Row],[Delivery SLA Status]]="SLA Breach","Critical - Late Delivery", Table1[[#This Row],[Customer_Rating]]<3,"Attention - Low Rating", TRUE,"Normal" )} -> Normal | AA73: =_xlfn.XLOOKUP(Table1[[#This Row],[Customer_ID]],Customers!A:A,Customers!C:C) -> Mumbai | AB73: =TEXT(Table1[[#This Row],[Order_Date]],"mmm") -> Jun
A74: ORD00036 | B74: 46167 | C74: CUST022 | D74: REST011 | E74: DP014 | F74: 1796.62 | G74: 50 | H74: 300 | I74: 6.5 | J74: 45 | K74: 4.5 | L74: Delivered | M74: =PROPER(TRIM(L74)) -> Delivered | N74: Credit Card | O74: =TRIM(N74) -> Credit Card | P74: PREMIUM10 | Q74: =TRIM(P74) -> PREMIUM10 | R74: CMP004 | T74: =_xlfn.XLOOKUP(Table1[[#This Row],[Customer_ID]],Customers!A:A,Customers!B:B) -> Neha Shinde | U74: =_xlfn.XLOOKUP(Table1[[#This Row],[Restaurant_ID]],Restaurants!A:A,Restaurants!B:B) -> Wok Express | V74: =_xlfn.XLOOKUP(Table1[[#This Row],[Delivery_Partner_ID]],Delivery_Partners!A:A,Delivery_Partners!B:B) -> Arjun | W74: =_xlfn.XLOOKUP(Table1[[#This Row],[Campaign_ID]],Campaigns!A:A,Campaigns!B:B) -> Lunch Saver | X74: =Table1[[#This Row],[Order_Value]]+Table1[[#This Row],[Delivery_Fee]]-Table1[[#This Row],[Discount]] -> 1546.62 | Y74: {=_xlfn.IFS(Table1[[#This Row],[Delivery_Time_Min]]<=30,"On Time",Table1[[#This Row],[Delivery_Time_Min]]<=45,"At Risk",TRUE,"SLA Breach")} -> At Risk | Z74: {=_xlfn.IFS( Table1[[#This Row],[Order_Status]]="Cancelled","Critical - Cancelled", Table1[[#This Row],[Delivery SLA Status]]="SLA Breach","Critical - Late Delivery", Table1[[#This Row],[Customer_Rating]]<3,"Attention - Low Rating", TRUE,"Normal" )} -> Normal | AA74: =_xlfn.XLOOKUP(Table1[[#This Row],[Customer_ID]],Customers!A:A,Customers!C:C) -> Hyderabad | AB74: =TEXT(Table1[[#This Row],[Order_Date]],"mmm") -> May
A75: ORD00038 | B75: 46196 | C75: CUST046 | D75: REST002 | E75: DP011 | F75: 1241.42 | G75: 25 | H75: 149.49 | I75: 4.9 | J75: 28 | K75: 4.5 | L75: Delivered | M75: =PROPER(TRIM(L75)) -> Delivered | N75: Wallet | O75: =TRIM(N75) -> Wallet | P75: LUNCH15 | Q75: =TRIM(P75) -> LUNCH15 | R75: CMP001 | T75: =_xlfn.XLOOKUP(Table1[[#This Row],[Customer_ID]],Customers!A:A,Customers!B:B) -> Aditya Shinde | U75: =_xlfn.XLOOKUP(Table1[[#This Row],[Restaurant_ID]],Restaurants!A:A,Restaurants!B:B) -> Urban Tadka | V75: =_xlfn.XLOOKUP(Table1[[#This Row],[Delivery_Partner_ID]],Delivery_Partners!A:A,Delivery_Partners!B:B) -> Prakash | W75: =_xlfn.XLOOKUP(Table1[[#This Row],[Campaign_ID]],Campaigns!A:A,Campaigns!B:B) -> Weekend Feast | X75: =Table1[[#This Row],[Order_Value]]+Table1[[#This Row],[Delivery_Fee]]-Table1[[#This Row],[Discount]] -> 1116.93 | Y75: {=_xlfn.IFS(Table1[[#This Row],[Delivery_Time_Min]]<=30,"On Time",Table1[[#This Row],[Delivery_Time_Min]]<=45,"At Risk",TRUE,"SLA Breach")} -> On Time | Z75: {=_xlfn.IFS( Table1[[#This Row],[Order_Status]]="Cancelled","Critical - Cancelled", Table1[[#This Row],[Delivery SLA Status]]="SLA Breach","Critical - Late Delivery", Table1[[#This Row],[Customer_Rating]]<3,"Attention - Low Rating", TRUE,"Normal" )} -> Normal | AA75: =_xlfn.XLOOKUP(Table1[[#This Row],[Customer_ID]],Customers!A:A,Customers!C:C) -> Pune | AB75: =TEXT(Table1[[#This Row],[Order_Date]],"mmm") -> Jun
A76: ORD00040 | B76: 46186 | C76: CUST001 | D76: REST025 | E76: DP011 | F76: 565.25 | G76: 30 | H76: 100.19 | I76: 4 | J76: 29 | K76: 3 | L76: Delivered | M76: =PROPER(TRIM(L76)) -> Delivered | N76: Debit Card | O76: =TRIM(N76) -> Debit Card | P76: MONSOON20 | Q76: =TRIM(P76) -> MONSOON20 | R76: CMP008 | T76: =_xlfn.XLOOKUP(Table1[[#This Row],[Customer_ID]],Customers!A:A,Customers!B:B) -> Neha Kulkarni | U76: =_xlfn.XLOOKUP(Table1[[#This Row],[Restaurant_ID]],Restaurants!A:A,Restaurants!B:B) -> Tandoor Tales | V76: =_xlfn.XLOOKUP(Table1[[#This Row],[Delivery_Partner_ID]],Delivery_Partners!A:A,Delivery_Partners!B:B) -> Prakash | W76: =_xlfn.XLOOKUP(Table1[[#This Row],[Campaign_ID]],Campaigns!A:A,Campaigns!B:B) -> Monsoon Meals | X76: =Table1[[#This Row],[Order_Value]]+Table1[[#This Row],[Delivery_Fee]]-Table1[[#This Row],[Discount]] -> 495.06 | Y76: {=_xlfn.IFS(Table1[[#This Row],[Delivery_Time_Min]]<=30,"On Time",Table1[[#This Row],[Delivery_Time_Min]]<=45,"At Risk",TRUE,"SLA Breach")} -> On Time | Z76: {=_xlfn.IFS( Table1[[#This Row],[Order_Status]]="Cancelled","Critical - Cancelled", Table1[[#This Row],[Delivery SLA Status]]="SLA Breach","Critical - Late Delivery", Table1[[#This Row],[Customer_Rating]]<3,"Attention - Low Rating", TRUE,"Normal" )} -> Normal | AA76: =_xlfn.XLOOKUP(Table1[[#This Row],[Customer_ID]],Customers!A:A,Customers!C:C) -> Nagpur | AB76: =TEXT(Table1[[#This Row],[Order_Date]],"mmm") -> Jun
